Workbook

Sheet Overview
A1: Layer 1 backend — complete project workbook
A2: Laravel 11 modular monolith. Layer 1 delivers the six Foundation modules that unblock all 119 frontend issues. Sources: DOC-10 (module architecture), DOC-02 (technical architecture and sprint plan), DOC-01 (business rules), DOC-06 (integration requirements).
A4: Contents
A5: Modules | B5: All 22 modules across the four layers, with the six that are in scope for Layer 1 flagged.
A6: Epics | B6: The eight backend epics with their volume and their backend sprint gate.
A7: Backlog | B7: Every backend issue with full requirements, acceptance criteria, tables, events and the frontend issues it unblocks.
A8: Delivery Plan | B8: Points and issue counts per sprint and module. All figures are live formulas over the Backlog sheet.
A9: Dependencies | B9: One row per blocking link between backend issues.
A10: API Delivery | B10: Every endpoint Layer 1 must ship, the backend issue that builds it, and the frontend issues waiting on it.
A11: Data Model | B11: The tables each Layer 1 module owns.
A12: Events | B12: Inter-module events, their emitter, their listeners and their effect.
A13: Conventions | B13: The binding conventions from DOC-10 §5 and the issue that enforces each one.
A14: Error Codes | B14: The HTTP status map and the internal error codes the frontend error map depends on.
A15: Business Rules | B15: BR-01…BR-20 and REQ-IN-01…08, with the owning module and the layer that enforces each.
A16: Risks | B16: Risk register with the backend issue that mitigates each risk.
A17: Jira Import | B17: Flat machine-readable sheet. Save this tab alone as CSV UTF-8 and import.
A19: Scope
A20: In scope | B20: The six Foundation modules: Core, Identity, Access, Reference, Tenancy, Integration — plus the SP-00 technical foundation and the quality gates.
A21: Out of scope | B21: The nine Domain modules and the seven Coordination modules. Catalog, Pricing, Promotion, Inventory, Ordering, Fulfillment, Delivery, Returns, Finance, Sync and Reporting all belong to Layers 2 and above.
A22: Why this boundary | B22: These six modules are exactly what the 119 frontend issues are gated on. Nothing above them can be built until identity, access, reference data and tenancy are real.
A24: Definition of done — applies to every issue
A25: 1. | B25: Merged to main after peer review; Larastan level 6, Pint and Rector all pass.
A26: 2. | B26: Unit and feature tests written and green; engines and money paths at 90%+, endpoints at 75%+.
A27: 3. | B27: Deptrac and the Pest architecture suite pass — no cross-module model import, no float in a money path.
A28: 4. | B28: Every write accepts X-Idempotency-Key unless it is on the documented exemption list.
A29: 5. | B29: Every channel endpoint has an isolation test proving another channel receives 404.
A30: 6. | B30: The endpoint declares its permission explicitly and returns the permission key on a 403.
A31: 7. | B31: Errors follow the unified envelope and the HTTP status map; no raw Laravel payload escapes.
A32: 8. | B32: Every financial, inventory or permission mutation writes an immutable audit entry.
A33: 9. | B33: The OpenAPI document is regenerated and the typed client still builds.
A34: 10. | B34: Deployed to the test environment and accepted by the product owner.
A36: Totals
A37: Backend issues | B37: =COUNTA(Backlog!A2:A98) -> 97
A38: Backend points | B38: =SUM(Backlog!M2:M98) -> 378
A39: Epics | B39: =COUNTA(Epics!A2:A50) -> 8
A40: Endpoints delivered | B40: =COUNTA('API Delivery'!A2:A200) -> 75
A41: Frontend issues unblocked | B41: 59
A42: Blocking links | B42: =COUNTA(Dependencies!A2:A300) -> 129

Sheet Modules
A1: # | B1: Module | C1: Layer | D1: In Layer 1 | E1: Responsibility | F1: Key tables
A2: 1 | B2: Core | C2: Foundation | D2: Yes | E2: Unified response envelope, error handler, idempotency, audit log, base classes, integer money | F2: audit_logs, idempotency_keys, approval_requests
A3: 2 | B3: Identity | C3: Foundation | D3: Yes | E3: The four guards, separate user tables, OTP, sessions, devices, session revocation | F3: platform_users, channel_users, warehouse_users, retailers, reps, otp_codes, devices, sessions
A4: 3 | B4: Access | C4: Foundation | D4: Yes | E4: The 170-permission catalog, roles, segregation of duties, temporary grants, periodic review, permission simulator | F4: permissions, roles, role_permission, sod_rules, temp_grants, access_reviews
A5: 4 | B5: Reference | C5: Foundation | D5: Yes | E5: Governorates, zones, activity types, root categories, sale units, equipment, currencies, FX rates | F5: governorates, zones, activity_types, root_categories, sale_units, equipments, currencies, fx_rates
A6: 5 | B6: Tenancy | C6: Foundation | D6: Yes | E6: Supply channels, provisioning, coverage, limits, plan binding, strict row-level isolation | F6: supply_channels, channel_zone, channel_limits, channel_features, provisioning_jobs
A7: 6 | B7: Integration | C7: Foundation | D7: Yes | E7: Provider adapters behind contracts: WhatsApp, SMS, maps, storage, notifications, error tracking | F7: integration_settings, integration_health
A8: 7 | B8: Catalog | C8: Domain | D8: No | E8: Brands, five-level category tree, products, variants, media, import | F8: brands, categories, products, product_variants, product_media, product_zones, import_batches
A9: 8 | B9: Pricing | C9: Domain | D9: No | E9: Pricing engine with five-rule precedence, tiers, zone / group / retailer prices, change log, price freeze | F9: price_lists, price_rules, qty_tiers, zone_prices, group_prices, retailer_prices, price_change_log
A10: 9 | B10: Promotion | C10: Domain | D10: No | E10: Six offer types, targeting, time and quantity limits, cart evaluation, indivisibility | F10: offers, offer_rules, offer_targets, offer_rewards, offer_usages
A11: 10 | B11: Inventory | C11: Domain | D11: No | E11: Warehouses, four balance states, movements, reservation, lots and expiry, stocktakes | F11: warehouses, stock_levels, stock_movements, reservations, lots, stocktakes
A12: 11 | B12: Loyalty | C12: Domain | D12: No | E12: Point rules, tiers, rewards, redemption | F12: loyalty_rules, loyalty_points, loyalty_tiers, rewards, redemptions
A13: 12 | B13: Content | C13: Domain | D13: No | E13: Intro, banners, sliders and algorithms, legal pages, app versions | F13: intros, banners, sliders, slider_items, legal_pages, app_versions
... A23: 22 | B23: Reporting | C23: Coordination | D23: No | E23: Daily snapshots, dashboards, reports, background export | F23: daily_snapshots, report_jobs, report_exports

Sheet Epics
A1: Epic key | B1: Epic name | C1: Covers | D1: Issues | E1: Points | F1: Sprint gates
A2: EP-BE-F | B2: SP-00 Technical foundation | C2: Repository, modules, Deptrac, CI, environments, OpenAPI, queues, health | D2: 10 | E2: 34 | F2: SP-00
A3: EP-BE-C | B3: Core module | C3: Envelope, error map, idempotency, audit, approvals, money, state machine base | D3: 10 | E3: 40 | F3: SP-00
A4: EP-BE-I | B4: Identity module | C4: Four guards, OTP, registration, sessions, devices, 2FA, API tokens | D4: 18 | E4: 70 | F4: SP-01, SP-04
A5: EP-BE-A | B5: Access module | C5: Permission catalog, roles, SoD, assignments, simulator, temp grants, audit, reviews | D5: 16 | E5: 67 | F5: SP-02
A6: EP-BE-R | B6: Reference module | C6: Seven reference entities, FX rates, public refs, import | D6: 12 | E6: 43 | F6: SP-03
A7: EP-BE-T | B7: Tenancy module | C7: Channels, provisioning, coverage, limits, isolation, applications | D7: 20 | E7: 86 | F7: SP-04
A8: EP-BE-X | B8: Integration module | C8: WhatsApp, SMS fallback, storage, error tracking behind contracts | D8: 5 | E8: 16 | F8: SP-00, SP-01
A9: EP-BE-Q | B9: Quality and hardening | C9: Architecture tests, isolation suite, contract snapshots, load and security | D9: 6 | E9: 22 | F9: SP-00, SP-01, SP-02, SP-04

Sheet Backlog
A1: Key | B1: Module | C1: Layer | D1: Title | E1: Epic | F1: Sprint gate | G1: Endpoints | H1: Tables | I1: Events | J1: Requirements | K1: Acceptance criteria | L1: Out of scope | M1: Points | N1: Priority | O1: Blocked by | P1: Unblocks frontend
A2: BE-F01 | B2: — | C2: Infrastructure | D2: Repository, Docker and the four environments | E2: EP-BE-F | F2: SP-00 | G2: Internal — no endpoint | H2: — | I2: — | J2: 1. Provision local Docker, test, staging (production-identical) and production environments. 2. Laravel 11 skeleton with app/ kept deliberately thin: Kernel, Providers and Console only. 3. Coding standards: Pint for formatting, Rector for upgrades, Larastan at level 6. 4. All business logic lives under app-modules/, never under app/. | K2: ☐ A merge to main deploys automatically to the test environment. ☐ Larastan level 6, Pint and Rector all pass with zero findings. ☐ app/ contains no controller, model or service. | L2: Nothing beyond the module scope. | M2: 5 | N2: Highest | O2: None | P2: —
A3: BE-F02 | B3: — | C3: Infrastructure | D3: Module scaffold with Composer path repositories | E3: EP-BE-F | F3: SP-00 | G3: Internal — no endpoint | H3: — | I3: — | J3: 1. Create app-modules/ with a local Composer path repository per module (b2b/core, b2b/identity, …). 2. Each module owns src/Contracts, Domain, Application, Infrastructure, Presentation, Database, Policies, config, lang, tests. 3. A module declares its dependencies in its own composer.json; a dependency it does not declare is not autoloadable. 4. Publish a module template so a new module is created identically every time. | K3: ☐ Importing a class from an undeclared module fails at autoload, not at review. ☐ The six Layer 1 modules exist and boot. ☐ A new module can be scaffolded from the template in one command. | L3: nwidart/laravel-modules or any dynamic module loader — explicitly rejected in DOC-10 §1.3. | M3: 5 | N3: Highest | O3: BE-F01 | P3: —
A4: BE-F03 | B4: — | C4: Infrastructure | D4: Deptrac dependency rules in CI | E4: EP-BE-F | F4: SP-00 | G4: Internal — no endpoint | H4: — | I4: — | J4: 1. Declare the four layers in deptrac.yaml: Foundation, Domain, Coordination, Presentation. 2. Ruleset: Coordination may depend on Domain and Foundation; Domain on Foundation; Foundation on nothing. 3. Run Deptrac in the pipeline and fail the build on a violation. | K4: ☐ A Foundation module importing a Domain class fails the build. ☐ The Deptrac report is attached to every pipeline run. | L4: Documenting the rule without enforcing it. A boundary CI does not check is a wish, not a boundary. | M4: 3 | N4: Highest | O4: BE-F02 | P4: —
A5: BE-F04 | B5: — | C5: Infrastructure | D5: Pest architecture tests | E5: EP-BE-F | F5: SP-00 | G5: Internal — no endpoint | H5: — | I5: — | J5: 1. No module imports another module Eloquent model (Modules\*\Domain\Models is module-private). 2. No float or double anywhere in a finance or money path. 3. Every channel controller is behind the channel guard middleware. 4. Cross-boundary references use identifiers, never Eloquent relations. | K5: ☐ Each rule has a failing example proving the test actually catches it. ☐ The suite runs in CI on every pull request. | L5: Nothing beyond the module scope. | M5: 3 | N5: Highest | O5: BE-F02 | P5: —
A6: BE-F05 | B6: — | C6: Infrastructure | D6: Base migrations and naming conventions | E6: EP-BE-F | F6: SP-00 | G6: Internal — no endpoint | H6: — | I6: — | J6: 1. Tables plural snake_case; columns snake_case with *_id foreign keys; routes kebab-case and plural. 2. States are a PHP Enum persisted as a string; events are past tense; jobs and actions are imperative verbs. 3. Each module owns its migrations, factories and seeders; only composite seeding lives in database/seeders. | K6: ☐ A convention violation is caught by a static check, not by a reviewer. ☐ Migrations are backward compatible so deployment never requires downtime. | L6: Nothing beyond the module scope. | M6: 3 | N6: High | O6: BE-F02 | P6: —
A7: BE-F06 | B7: — | C7: Infrastructure | D7: OpenAPI contract and generated clients | E7: EP-BE-F | F7: SP-00 | G7: Internal — no endpoint | H7: — | I7: — | J7: 1. Generate the OpenAPI document from the route and resource definitions. 2. Generate a typed TypeScript client and Zod schemas for the three web frontends. 3. The catalog fields b (request body), r (data shape) and e (error codes) are the contract of record. | K7: ☐ A frontend developer writes no type by hand. ☐ A server-side shape change breaks the frontend build rather than failing silently at runtime. | L7: Nothing beyond the module scope. | M7: 5 | N7: High | O7: BE-F01 | P7: —
A8: BE-F07 | B8: — | C8: Infrastructure | D8: Queues and Horizon | E8: EP-BE-F | F8: SP-00 | G8: Internal — no endpoint | H8: — | I8: — | J8: 1. Four queues by priority: critical (OTP, handover, payments, outbox intake), default, media, reports. 2. Horizon supervises the workers and feeds the system-health screen. 3. Alert on queue backlog and on rising latency. | K8: ☐ An OTP job never waits behind a report job. ☐ Horizon shows all four queues with their configured priorities. | L8: Nothing beyond the module scope. | M8: 3 | N8: High | O8: BE-F01 | P8: —
A9: BE-F08 | B9: — | C9: Infrastructure | D9: Observability: Sentry, Pulse and alerting | E9: EP-BE-F | F9: SP-00 | G9: Internal — no endpoint | H9: — | I9: — | J9: 1. Sentry for errors, Pulse for application performance. 2. Phone numbers and tokens are masked in every log line. 3. Alerts on queue backlog, response-time regression and error-rate spikes. | K9: ☐ No log line anywhere contains a full phone number or a token. ☐ An induced 500 reaches Sentry with the request context attached. | L9: Nothing beyond the module scope. | M9: 3 | N9: Medium | O9: BE-F01 | P9: —
A10: BE-F09 | B10: Core | C10: Foundation | D10: Health endpoint | E10: EP-BE-F | F10: SP-00 | G10: EP-CORE-001 | H10: — | I10: — | J10: 1. GET /api/v1/health returns data.status = ok with no authentication and no idempotency key. 2. Report database, cache and queue reachability. | K10: ☐ The endpoint answers without a Bearer token. ☐ It is the first endpoint the shared frontend kit calls successfully. | L10: Nothing beyond the module scope. | M10: 1 | N10: Highest | O10: BE-C01 | P10: FE-CORE-01
A11: BE-F10 | B11: — | C11: Infrastructure | D11: Zero-downtime deployment pipeline | E11: EP-BE-F | F11: SP-00 | G11: Internal — no endpoint | H11: — | I11: — | J11: 1. Pipeline: static analysis → tests → frontend build → Docker image → zero-downtime deploy with safe migration. 2. Encrypted daily off-server backup with a documented monthly restore test. | K11: ☐ A deployment causes no request failure. ☐ A restore test is executed and recorded before L1 closes. | L11: Nothing beyond the module scope. | M11: 3 | N11: Medium | O11: BE-F01 | P11: —
A12: BE-C01 | B12: Core | C12: Foundation | D12: Unified response envelope | E12: EP-BE-C | F12: SP-00 | G12: Internal — no endpoint | H12: — | I12: — | J12: 1. Success: { data, meta.server_time } plus meta.sync_cursor where the module provides one. 2. List success adds meta.page, per_page, total and last_page. 3. Error: { error: { code, message, details?, permission? } } — never a raw Laravel validation payload. | K12: ☐ A snapshot test pins the envelope shape for the mobile clients. ☐ No controller returns a bare array or a raw model. | L12: Nothing beyond the module scope. | M12: 3 | N12: Highest | O12: BE-F02 | P12: —
A13: BE-C02 | B13: Core | C13: Foundation | D13: Error handler and HTTP status map | E13: EP-BE-C | F13: SP-00 | G13: Internal — no endpoint | H13: — | I13: — | J13: 1. 401 unauthenticated, token_revoked. 403 wrong_guard, insufficient_permission, requires_2fa, requires_password_confirm. 2. 404 not_found for out-of-tenant access. 409 illegal_transition, operation_in_progress, stale_version. 3. 422 validation_failed with details keyed by field. 423 plan_limit_exceeded. 426 upgrade_required. 429 rate_limited. 503 maintenance_mode. 4. Messages are Arabic and translatable; the code is the contract, the message is for the human. | K13: ☐ Every code in the map has a feature test that triggers it. ☐ A 403 for a permission failure carries the permission key in the payload. ☐ Out-of-tenant access returns 404, never 403 — existence is not disclosed. | L13: Nothing beyond the module scope. | M13: 5 | N13: Highest | O13: BE-C01 | P13: —
... A98: BE-Q06 | B98: — | C98: Quality | D98: Security hardening pass | E98: EP-BE-Q | F98: SP-02 | G98: Internal — no endpoint | H98: — | I98: — | J98: 1. TLS enforced, full security headers, CSRF protection on the dashboards. 2. Sensitive fields encrypted at rest; phone numbers masked in logs. 3. Strict rate limiting on OTP and login with progressive temporary blocks. 4. Encrypted daily off-server backup with a documented restore test. | K98: ☐ A plain HTTP request is refused, not redirected. ☐ The restore test is executed and recorded before L1 closes. | L98: Nothing beyond the module scope. | M98: 5 | N98: High | O98: BE-C08, BE-A16 | P98: —

Sheet Delivery Plan
A1: Delivery plan — every figure is a live formula over the Backlog sheet
A2: The sprint gate is the backend sprint that must close before the corresponding frontend issues can be pulled. It is a dependency statement, not a capacity plan.
A4: Backend points by sprint gate and module
B5: Core | C5: Identity | D5: Access | E5: Reference | F5: Tenancy | G5: Integration | H5: — | I5: Total
A6: SP-00 | B6: =SUMIFS(Backlog!$M$2:$M$98,Backlog!$F$2:$F$98,"SP-00",Backlog!$B$2:$B$98,"Core") -> 41 | C6: =SUMIFS(Backlog!$M$2:$M$98,Backlog!$F$2:$F$98,"SP-00",Backlog!$B$2:$B$98,"Identity") -> 0 | D6: =SUMIFS(Backlog!$M$2:$M$98,Backlog!$F$2:$F$98,"SP-00",Backlog!$B$2:$B$98,"Access") -> 0 | E6: =SUMIFS(Backlog!$M$2:$M$98,Backlog!$F$2:$F$98,"SP-00",Backlog!$B$2:$B$98,"Reference") -> 0 | F6: =SUMIFS(Backlog!$M$2:$M$98,Backlog!$F$2:$F$98,"SP-00",Backlog!$B$2:$B$98,"Tenancy") -> 0 | G6: =SUMIFS(Backlog!$M$2:$M$98,Backlog!$F$2:$F$98,"SP-00",Backlog!$B$2:$B$98,"Integration") -> 2 | H6: =SUMIFS(Backlog!$M$2:$M$98,Backlog!$F$2:$F$98,"SP-00",Backlog!$B$2:$B$98,"—") -> 36 | I6: =SUM(B6:H6) -> 79
A7: SP-01 | B7: =SUMIFS(Backlog!$M$2:$M$98,Backlog!$F$2:$F$98,"SP-01",Backlog!$B$2:$B$98,"Core") -> 0 | C7: =SUMIFS(Backlog!$M$2:$M$98,Backlog!$F$2:$F$98,"SP-01",Backlog!$B$2:$B$98,"Identity") -> 65 | D7: =SUMIFS(Backlog!$M$2:$M$98,Backlog!$F$2:$F$98,"SP-01",Backlog!$B$2:$B$98,"Access") -> 0 | E7: =SUMIFS(Backlog!$M$2:$M$98,Backlog!$F$2:$F$98,"SP-01",Backlog!$B$2:$B$98,"Reference") -> 0 | F7: =SUMIFS(Backlog!$M$2:$M$98,Backlog!$F$2:$F$98,"SP-01",Backlog!$B$2:$B$98,"Tenancy") -> 0 | G7: =SUMIFS(Backlog!$M$2:$M$98,Backlog!$F$2:$F$98,"SP-01",Backlog!$B$2:$B$98,"Integration") -> 14 | H7: =SUMIFS(Backlog!$M$2:$M$98,Backlog!$F$2:$F$98,"SP-01",Backlog!$B$2:$B$98,"—") -> 6 | I7: =SUM(B7:H7) -> 85
A8: SP-02 | B8: =SUMIFS(Backlog!$M$2:$M$98,Backlog!$F$2:$F$98,"SP-02",Backlog!$B$2:$B$98,"Core") -> 0 | C8: =SUMIFS(Backlog!$M$2:$M$98,Backlog!$F$2:$F$98,"SP-02",Backlog!$B$2:$B$98,"Identity") -> 0 | D8: =SUMIFS(Backlog!$M$2:$M$98,Backlog!$F$2:$F$98,"SP-02",Backlog!$B$2:$B$98,"Access") -> 67 | E8: =SUMIFS(Backlog!$M$2:$M$98,Backlog!$F$2:$F$98,"SP-02",Backlog!$B$2:$B$98,"Reference") -> 0 | F8: =SUMIFS(Backlog!$M$2:$M$98,Backlog!$F$2:$F$98,"SP-02",Backlog!$B$2:$B$98,"Tenancy") -> 0 | G8: =SUMIFS(Backlog!$M$2:$M$98,Backlog!$F$2:$F$98,"SP-02",Backlog!$B$2:$B$98,"Integration") -> 0 | H8: =SUMIFS(Backlog!$M$2:$M$98,Backlog!$F$2:$F$98,"SP-02",Backlog!$B$2:$B$98,"—") -> 10 | I8: =SUM(B8:H8) -> 77
A9: SP-03 | B9: =SUMIFS(Backlog!$M$2:$M$98,Backlog!$F$2:$F$98,"SP-03",Backlog!$B$2:$B$98,"Core") -> 0 | C9: =SUMIFS(Backlog!$M$2:$M$98,Backlog!$F$2:$F$98,"SP-03",Backlog!$B$2:$B$98,"Identity") -> 0 | D9: =SUMIFS(Backlog!$M$2:$M$98,Backlog!$F$2:$F$98,"SP-03",Backlog!$B$2:$B$98,"Access") -> 0 | E9: =SUMIFS(Backlog!$M$2:$M$98,Backlog!$F$2:$F$98,"SP-03",Backlog!$B$2:$B$98,"Reference") -> 43 | F9: =SUMIFS(Backlog!$M$2:$M$98,Backlog!$F$2:$F$98,"SP-03",Backlog!$B$2:$B$98,"Tenancy") -> 0 | G9: =SUMIFS(Backlog!$M$2:$M$98,Backlog!$F$2:$F$98,"SP-03",Backlog!$B$2:$B$98,"Integration") -> 0 | H9: =SUMIFS(Backlog!$M$2:$M$98,Backlog!$F$2:$F$98,"SP-03",Backlog!$B$2:$B$98,"—") -> 0 | I9: =SUM(B9:H9) -> 43
A10: SP-04 | B10: =SUMIFS(Backlog!$M$2:$M$98,Backlog!$F$2:$F$98,"SP-04",Backlog!$B$2:$B$98,"Core") -> 0 | C10: =SUMIFS(Backlog!$M$2:$M$98,Backlog!$F$2:$F$98,"SP-04",Backlog!$B$2:$B$98,"Identity") -> 5 | D10: =SUMIFS(Backlog!$M$2:$M$98,Backlog!$F$2:$F$98,"SP-04",Backlog!$B$2:$B$98,"Access") -> 0 | E10: =SUMIFS(Backlog!$M$2:$M$98,Backlog!$F$2:$F$98,"SP-04",Backlog!$B$2:$B$98,"Reference") -> 0 | F10: =SUMIFS(Backlog!$M$2:$M$98,Backlog!$F$2:$F$98,"SP-04",Backlog!$B$2:$B$98,"Tenancy") -> 86 | G10: =SUMIFS(Backlog!$M$2:$M$98,Backlog!$F$2:$F$98,"SP-04",Backlog!$B$2:$B$98,"Integration") -> 0 | H10: =SUMIFS(Backlog!$M$2:$M$98,Backlog!$F$2:$F$98,"SP-04",Backlog!$B$2:$B$98,"—") -> 3 | I10: =SUM(B10:H10) -> 94
A11: Total | B11: =SUM(B6:B10) -> 41 | C11: =SUM(C6:C10) -> 70 | D11: =SUM(D6:D10) -> 67 | E11: =SUM(E6:E10) -> 43 | F11: =SUM(F6:F10) -> 86 | G11: =SUM(G6:G10) -> 16 | H11: =SUM(H6:H10) -> 55 | I11: =SUM(I6:I10) -> 378
A14: Backend issue count by sprint gate and module
B15: Core | C15: Identity | D15: Access | E15: Reference | F15: Tenancy | G15: Integration | H15: — | I15: Total
A16: SP-00 | B16: =COUNTIFS(Backlog!$F$2:$F$98,"SP-00",Backlog!$B$2:$B$98,"Core") -> 11 | C16: =COUNTIFS(Backlog!$F$2:$F$98,"SP-00",Backlog!$B$2:$B$98,"Identity") -> 0 | D16: =COUNTIFS(Backlog!$F$2:$F$98,"SP-00",Backlog!$B$2:$B$98,"Access") -> 0 | E16: =COUNTIFS(Backlog!$F$2:$F$98,"SP-00",Backlog!$B$2:$B$98,"Reference") -> 0 | F16: =COUNTIFS(Backlog!$F$2:$F$98,"SP-00",Backlog!$B$2:$B$98,"Tenancy") -> 0 | G16: =COUNTIFS(Backlog!$F$2:$F$98,"SP-00",Backlog!$B$2:$B$98,"Integration") -> 1 | H16: =COUNTIFS(Backlog!$F$2:$F$98,"SP-00",Backlog!$B$2:$B$98,"—") -> 10 | I16: =SUM(B16:H16) -> 22
A17: SP-01 | B17: =COUNTIFS(Backlog!$F$2:$F$98,"SP-01",Backlog!$B$2:$B$98,"Core") -> 0 | C17: =COUNTIFS(Backlog!$F$2:$F$98,"SP-01",Backlog!$B$2:$B$98,"Identity") -> 17 | D17: =COUNTIFS(Backlog!$F$2:$F$98,"SP-01",Backlog!$B$2:$B$98,"Access") -> 0 | E17: =COUNTIFS(Backlog!$F$2:$F$98,"SP-01",Backlog!$B$2:$B$98,"Reference") -> 0 | F17: =COUNTIFS(Backlog!$F$2:$F$98,"SP-01",Backlog!$B$2:$B$98,"Tenancy") -> 0 | G17: =COUNTIFS(Backlog!$F$2:$F$98,"SP-01",Backlog!$B$2:$B$98,"Integration") -> 4 | H17: =COUNTIFS(Backlog!$F$2:$F$98,"SP-01",Backlog!$B$2:$B$98,"—") -> 2 | I17: =SUM(B17:H17) -> 23
A18: SP-02 | B18: =COUNTIFS(Backlog!$F$2:$F$98,"SP-02",Backlog!$B$2:$B$98,"Core") -> 0 | C18: =COUNTIFS(Backlog!$F$2:$F$98,"SP-02",Backlog!$B$2:$B$98,"Identity") -> 0 | D18: =COUNTIFS(Backlog!$F$2:$F$98,"SP-02",Backlog!$B$2:$B$98,"Access") -> 16 | E18: =COUNTIFS(Backlog!$F$2:$F$98,"SP-02",Backlog!$B$2:$B$98,"Reference") -> 0 | F18: =COUNTIFS(Backlog!$F$2:$F$98,"SP-02",Backlog!$B$2:$B$98,"Tenancy") -> 0 | G18: =COUNTIFS(Backlog!$F$2:$F$98,"SP-02",Backlog!$B$2:$B$98,"Integration") -> 0 | H18: =COUNTIFS(Backlog!$F$2:$F$98,"SP-02",Backlog!$B$2:$B$98,"—") -> 2 | I18: =SUM(B18:H18) -> 18
A19: SP-03 | B19: =COUNTIFS(Backlog!$F$2:$F$98,"SP-03",Backlog!$B$2:$B$98,"Core") -> 0 | C19: =COUNTIFS(Backlog!$F$2:$F$98,"SP-03",Backlog!$B$2:$B$98,"Identity") -> 0 | D19: =COUNTIFS(Backlog!$F$2:$F$98,"SP-03",Backlog!$B$2:$B$98,"Access") -> 0 | E19: =COUNTIFS(Backlog!$F$2:$F$98,"SP-03",Backlog!$B$2:$B$98,"Reference") -> 12 | F19: =COUNTIFS(Backlog!$F$2:$F$98,"SP-03",Backlog!$B$2:$B$98,"Tenancy") -> 0 | G19: =COUNTIFS(Backlog!$F$2:$F$98,"SP-03",Backlog!$B$2:$B$98,"Integration") -> 0 | H19: =COUNTIFS(Backlog!$F$2:$F$98,"SP-03",Backlog!$B$2:$B$98,"—") -> 0 | I19: =SUM(B19:H19) -> 12
A20: SP-04 | B20: =COUNTIFS(Backlog!$F$2:$F$98,"SP-04",Backlog!$B$2:$B$98,"Core") -> 0 | C20: =COUNTIFS(Backlog!$F$2:$F$98,"SP-04",Backlog!$B$2:$B$98,"Identity") -> 1 | D20: =COUNTIFS(Backlog!$F$2:$F$98,"SP-04",Backlog!$B$2:$B$98,"Access") -> 0 | E20: =COUNTIFS(Backlog!$F$2:$F$98,"SP-04",Backlog!$B$2:$B$98,"Reference") -> 0 | F20: =COUNTIFS(Backlog!$F$2:$F$98,"SP-04",Backlog!$B$2:$B$98,"Tenancy") -> 20 | G20: =COUNTIFS(Backlog!$F$2:$F$98,"SP-04",Backlog!$B$2:$B$98,"Integration") -> 0 | H20: =COUNTIFS(Backlog!$F$2:$F$98,"SP-04",Backlog!$B$2:$B$98,"—") -> 1 | I20: =SUM(B20:H20) -> 22
A21: Total | B21: =SUM(B16:B20) -> 11 | C21: =SUM(C16:C20) -> 18 | D21: =SUM(D16:D20) -> 16 | E21: =SUM(E16:E20) -> 12 | F21: =SUM(F16:F20) -> 20 | G21: =SUM(G16:G20) -> 5 | H21: =SUM(H16:H20) -> 15 | I21: =SUM(I16:I20) -> 97
A24: Frontend issues unblocked per backend sprint
A25: Sprint gate | B25: Frontend issues waiting | C25: Backend points required | D25: What it delivers
A26: SP-00 | B26: 10 | C26: 79 | D26: Technical foundation, Core module, health endpoint, guardrails
A27: SP-01 | B27: 54 | C27: 85 | D27: Identity: four guards, OTP, registration, sessions, 2FA, integrations
A28: SP-02 | B28: 15 | C28: 77 | D28: Access: permission catalog, roles, dual approval, audit, reviews
A29: SP-03 | B29: 15 | C29: 43 | D29: Reference: seven entities, FX, public refs, import
A30: SP-04 | B30: 25 | C30: 94 | D30: Tenancy: channels, provisioning, coverage, limits, isolation
A33: • | B33: SP-00 and SP-01 together are 60 percent of the backend effort and unblock nothing visible. That is correct: the foundation is where the boundaries, the money type, the idempotency and the audit trail are decided, and none of them can be retrofitted.
A34: • | B34: SP-04 has the smallest frontend fan-out per point, but it is the gate for the rep app entirely: without a real channel_id there is no invite link, and without an invite link the rep app cannot register anyone.
A35: • | B35: The backend can run one sprint ahead of the frontend throughout. It must never run behind: a frontend team blocked on a contract is a team writing mock data, and mock data is what the frontend guardrails exist to reject.

Sheet Dependencies
A1: Blocker | B1: Blocker title | C1: Blocker module | D1: Blocker sprint | E1: Blocked | F1: Blocked title | G1: Blocked module | H1: Blocked sprint | I1: Cross-module
A2: BE-A01 | B2: Permission catalog seed | C2: Access | D2: SP-02 | E2: BE-A02 | F2: Permission catalog and holders API | G2: Access | H2: SP-02 | I2: No
A3: BE-A01 | B3: Permission catalog seed | C3: Access | D3: SP-02 | E3: BE-A03 | F3: Roles with draft lifecycle | G3: Access | H3: SP-02 | I3: No
A4: BE-A01 | B4: Permission catalog seed | C4: Access | D4: SP-02 | E4: BE-A11 | F4: Segregation of duties rules | G4: Access | H4: SP-02 | I4: No
A5: BE-A01 | B5: Permission catalog seed | C5: Access | D5: SP-02 | E5: BE-A16 | F5: Two-level authorisation enforcement | G5: Access | H5: SP-02 | I5: No
A6: BE-A03 | B6: Roles with draft lifecycle | C6: Access | D6: SP-02 | E6: BE-A04 | F6: Role preview with SoD conflict detection | G6: Access | H6: SP-02 | I6: No
A7: BE-A03 | B7: Roles with draft lifecycle | C7: Access | D7: SP-02 | E7: BE-A05 | F7: Role approval by a second user | G7: Access | H7: SP-02 | I7: No
A8: BE-A03 | B8: Roles with draft lifecycle | C8: Access | D8: SP-02 | E8: BE-A06 | F8: Replace role permissions | G8: Access | H8: SP-02 | I8: No
A9: BE-A03 | B9: Roles with draft lifecycle | C9: Access | D9: SP-02 | E9: BE-A07 | F9: Bulk role assignment | G9: Access | H9: SP-02 | I9: No
A10: BE-A03 | B10: Roles with draft lifecycle | C10: Access | D10: SP-02 | E10: BE-A09 | F10: Permission simulator | G10: Access | H10: SP-02 | I10: No
A11: BE-A07 | B11: Bulk role assignment | C11: Access | D11: SP-02 | E11: BE-A08 | F11: Revoke assignment | G11: Access | H11: SP-02 | I11: No
A12: BE-A07 | B12: Bulk role assignment | C12: Access | D12: SP-02 | E12: BE-A15 | F12: Quarterly access review campaigns | G12: Access | H12: SP-02 | I12: No
... A130: BE-X01 | B130: WhatsApp Business API adapter | C130: Integration | D130: SP-01 | E130: BE-X05 | F130: Integration health and settings | G130: Integration | H130: SP-01 | I130: No

Sheet API Delivery
A1: EP-ID | B1: Built by | C1: Backend issue title | D1: Module | E1: Sprint gate | F1: Frontend consumers | G1: Consumer count
A2: EP-AD-001 | B2: BE-I12 | C2: Platform login and TOTP | D2: Identity | E2: SP-01 | F2: AD-10 | G2: 1
A3: EP-AD-002 | B3: BE-I12 | C3: Platform login and TOTP | D3: Identity | E3: SP-01 | F3: AD-11 | G3: 1
A4: EP-AD-003 | B4: BE-I12 | C4: Platform login and TOTP | D4: Identity | E4: SP-01 | F4: AD-13 | G4: 1
A5: EP-AD-004 | B5: BE-I13 | C5: Platform account profile and password | D5: Identity | E5: SP-01 | F5: AD-12 | G5: 1
A6: EP-AD-005 | B6: BE-I17 | C6: Password confirmation window | D6: Identity | E6: SP-01 | F6: AD-03 | G6: 1
A7: EP-AD-006 | B7: BE-I14 | C7: Session listing and revocation | D7: Identity | E7: SP-01 | F7: AD-16 | G7: 1
A8: EP-AD-007 | B8: BE-I14 | C8: Session listing and revocation | D8: Identity | E8: SP-01 | F8: None yet in the L1 frontend backlog | G8: 0
A9: EP-AD-030 | B9: BE-R02 | C9: Governorates | D9: Reference | E9: SP-03 | F9: AD-41 | G9: 1
A10: EP-AD-031 | B10: BE-R02 | C10: Governorates | D10: Reference | E10: SP-03 | F10: None yet in the L1 frontend backlog | G10: 0
A11: EP-AD-032 | B11: BE-R03 | C11: Zones with impact counts | D11: Reference | E11: SP-03 | F11: AD-42 | G11: 1
A12: EP-AD-033 | B12: BE-R03 | C12: Zones with impact counts | D12: Reference | E12: SP-03 | F12: None yet in the L1 frontend backlog | G12: 0
A13: EP-AD-034 | B13: BE-R03 | C13: Zones with impact counts | D13: Reference | E13: SP-03 | F13: AD-49 | G13: 1
... A76: EP-WH-001 | B76: BE-I11 | C76: Warehouse device provisioning and login | D76: Identity | E76: SP-01 | F76: WH-03 | G76: 1

Sheet Data Model
A1: Module | B1: Table | C1: Owned by issue | D1: Sprint gate | E1: Notes
A2: Access | B2: access_reviews | C2: BE-A15 | D2: SP-02
A3: Access | B3: permissions | C3: BE-A01 | D3: SP-02
A4: Access | B4: role_permission | C4: BE-A03 | D4: SP-02
A5: Access | B5: roles | C5: BE-A03 | D5: SP-02
A6: Access | B6: sod_rules | C6: BE-A11 | D6: SP-02
A7: Access | B7: temp_grants | C7: BE-A10 | D7: SP-02
A8: Core | B8: approval_requests | C8: BE-C05 | D8: SP-00 | E8: Generic dual-approval store; every sensitive action defers through it.
A9: Core | B9: audit_logs | C9: BE-C04 | D9: SP-00 | E9: Immutable: no update and no delete path exists. Two-year retention (BR-16).
A10: Core | B10: idempotency_keys | C10: BE-C03 | D10: SP-00 | E10: Stores the response for 24 hours; the technical basis of REQ-IN-01 and AC-05.
A11: Identity | B11: channel_users | C11: BE-I01 | D11: SP-01
A12: Identity | B12: devices | C12: BE-I04 | D12: SP-01
A13: Identity | B13: otp_codes | C13: BE-I02 | D13: SP-01 | E13: Codes hashed, five-minute expiry, attempt capped.
A14: Identity | B14: platform_users | C14: BE-I01 | D14: SP-01
A15: Identity | B15: reps | C15: BE-I01 | D15: SP-01
A16: Identity | B16: retailers | C16: BE-I01 | D16: SP-01
A17: Identity | B17: sessions | C17: BE-I04 | D17: SP-01
A18: Identity | B18: warehouse_users | C18: BE-I01 | D18: SP-01
A19: Integration | B19: integration_health | C19: BE-X05 | D19: SP-01
A20: Integration | B20: integration_settings | C20: BE-X01 | D20: SP-01
A21: Reference | B21: activity_types | C21: BE-R04 | D21: SP-03
A22: Reference | B22: currencies | C22: BE-R08 | D22: SP-03
A23: Reference | B23: equipments | C23: BE-R07 | D23: SP-03
A24: Reference | B24: fx_rates | C24: BE-R09 | D24: SP-03 | E24: rate is an integer. A rate change never reprices an existing order (BR-AD-19).
A25: Reference | B25: governorates | C25: BE-R02 | D25: SP-03
A26: Reference | B26: import_batches | C26: BE-R11 | D26: SP-03
A27: Reference | B27: root_categories | C27: BE-R05 | D27: SP-03
A28: Reference | B28: sale_units | C28: BE-R06 | D28: SP-03
A29: Reference | B29: zones | C29: BE-R03 | D29: SP-03 | E29: Status changes go through route 034, not the 043 family — documented contract exception.
A30: Tenancy | B30: channel_applications | C30: BE-T19 | D30: SP-04
A31: Tenancy | B31: channel_features | C31: BE-T10 | D31: SP-04
A32: Tenancy | B32: channel_limits | C32: BE-T04 | D32: SP-04
A33: Tenancy | B33: channel_zone | C33: BE-T08 | D33: SP-04 | E33: Coverage: warehouse, delivery days, delivery fee, minimum order value, price list per zone.
A34: Tenancy | B34: provisioning_jobs | C34: BE-T05 | D34: SP-04
A35: Tenancy | B35: supply_channels | C35: BE-T01 | D35: SP-04 | E35: The tenant root. Every channel-owned table carries supply_channel_id.
A36: Tenancy | B36: warehouses | C36: BE-T09 | D36: SP-04

Sheet Events
A1: Event | B1: Emitted by | C1: Listened to by | D1: Effect | E1: Layer
A2: ChannelStatusChanged | B2: Tenancy | C2: Ordering, Notification, Reporting | D2: Freezes new orders only (BR-AD-14) | E2: L1
A3: ReferenceDisabled | B3: Reference | C3: Catalog, Tenancy, Ordering | D3: Blocks new use without touching existing records | E3: L1
A4: OrderSubmitted | B4: Ordering | C4: Inventory, Notification, Reporting | D4: No reservation yet — channel notification only | E4: Layer 2
A5: SubOrderConfirmed | B5: Ordering | C5: Inventory, Fulfillment, Notification | D5: Reserve stock and create the picking list (BR-05) | E5: Layer 2
A6: HandoverCompleted | B6: Fulfillment | C6: Inventory, Ordering, Notification | D6: Actual stock deduction and the on_the_way state | E6: Layer 3
A7: DeliveryCompleted | B7: Delivery | C7: Finance, Loyalty, Notification | D7: Generate the invoice, create the receivable, award points | E7: Layer 3
A8: PaymentRecorded | B8: Finance | C8: Finance/Wallet, Notification, Reporting | D8: Increase the rep wallet and reduce the retailer receivable | E8: Layer 3
A9: ReturnApproved | B9: Returns | C9: Finance, Inventory | D9: Credit note plus stock return according to condition | E9: Layer 3
A10: PriceListChanged | B10: Pricing | C10: Sync, Reporting | D10: Marks data for differential sync; never touches a live order | E10: Layer 2

Sheet Conventions
A1: Area | B1: Binding convention | C1: Source | D1: Enforced by
A2: Modules | B2: app-modules/ with local Composer path repositories; boundaries enforced by Deptrac in CI | C2: DOC-10 §1.3, §4.3 | D2: BE-F02 / BE-F03
A3: Dependency direction | B3: Downward only. Coordination → Domain → Foundation. Foundation depends on nothing. | C3: DOC-10 §2.1 | D3: BE-F03
A4: Cross-module calls | B4: Public Contracts or events only. Never another module Eloquent model, never its tables. | C4: DOC-10 §2.2 | D4: BE-F04
A5: Cross-module relations | B5: By identifier, never by an Eloquent relation across a boundary. | C5: DOC-10 §2.2 | D5: BE-F04
A6: Events | B6: Notification, not control. The emitting module does not wait for a result. | C6: DOC-10 §2.2 | D6: BE-C07
A7: Tenancy | B7: supply_channel_id on every channel-owned table with a composite index starting on it; ChannelScope applied automatically. | C7: DOC-10 §5.1, DOC-02 §7.4 | D7: BE-T02
A8: Tenancy failure mode | B8: A foreign channel id in the URL returns 404, not 403. | C8: DOC-10 §5.1 (AC-PM-02) | D8: BE-T02
A9: Money | B9: bigInteger in the smallest currency unit plus a Money value object. float and double are forbidden. | C9: DOC-10 §5.2 (BR-AD-18) | D9: BE-C06
A10: Money presentation | B10: Rounding happens in MoneyResource only; storage stays integer. | C10: DOC-10 §5.2 | D10: BE-C06
A11: State machines | B11: status is guarded and changed only through the lifecycle service; every transition is logged; an illegal transition raises 409. | C11: DOC-10 §5.3 (BR-AD-13) | D11: BE-C07
A12: Idempotency | B12: Every write accepts X-Idempotency-Key. Completed key replays, in-flight key returns 409, new key executes and stores for 24 hours. | C12: DOC-10 §5.4 (BR-AD-24) | D12: BE-C03
... A19: Testing | B19: Unit ≥ 90% on engines and money; feature ≥ 75% on endpoints, permissions and isolation; Larastan level 6. | C19: DOC-02 §17 | D19: BE-Q04

Sheet Error Codes
A1: HTTP | B1: Internal codes | C1: When | D1: Owning issue
A2: 401 | B2: unauthenticated, token_revoked | C2: Authentication failed or the token was revoked | D2: BE-C02 / BE-I09
A3: 403 | B3: wrong_guard, insufficient_permission, requires_2fa, requires_password_confirm, sod_violation | C3: Guard or permission failure, or a step-up challenge | D3: BE-C02 / BE-A16 / BE-I17
A4: 404 | B4: not_found | C4: Outside the tenant scope, or genuinely absent — existence is never disclosed | D4: BE-T02
A5: 409 | B5: illegal_transition, operation_in_progress, stale_version, idempotency_key_conflict, conflict | C5: State conflict or an operation already in flight | D5: BE-C03 / BE-C07
A6: 422 | B6: validation_failed, ref_in_use | C6: Input validation, keyed by field in details | D6: BE-C02
A7: 423 | B7: plan_limit_exceeded | C7: The channel exceeded a plan limit | D7: BE-T12
A8: 426 | B8: upgrade_required | C8: The app version is below the supported minimum | D8: BE-C02
A9: 429 | B9: rate_limited | C9: Rate limit exceeded; Retry-After is set | D9: BE-C08
A10: 503 | B10: maintenance_mode | C10: Planned maintenance | D10: BE-C02

Sheet Business Rules
A1: Rule | B1: Statement | C1: Owning module | D1: Enforced in
A2: BR-01 | B2: A multi-channel order is split automatically at submission into independent sub-orders, each with its own number, invoice, route and rep. | C2: Ordering | D2: Layer 2
A3: BR-02 | B3: The supply channel name is not disclosed to the retailer before the sub-order is confirmed. | C3: Ordering / Core | D3: Layer 2
A4: BR-03 | B4: The rep name and phone are not disclosed before the order reaches on_the_way. | C4: Delivery | D4: Layer 3
A5: BR-04 | B5: The price is frozen on the order at submission and is unaffected by any later price-list change. | C5: Pricing | D5: Layer 2
A6: BR-05 | B6: Stock reservation starts at confirmation; the actual deduction happens at handover to the rep. | C6: Inventory | D6: Layer 3
A7: BR-06 | B7: Cancellation by the retailer is permitted in the pending state only. | C7: Ordering | D7: Layer 2
A8: BR-07 | B8: The cart is emptied automatically after a successful submission and held locally before it. | C8: Ordering | D8: Layer 2
A9: BR-08 | B9: A composite offer is indivisible on add, remove and return. | C9: Promotion | D9: Layer 2
A10: BR-09 | B10: An invoice discount applies only to the portion of the multi-channel order belonging to that channel. | C10: Promotion / Finance | D10: Layer 2
A11: BR-10 | B11: A posted invoice cannot be edited; corrections are made by a linked credit or debit note. | C11: Finance | D11: Layer 3
A12: BR-11 | B12: Every payment is documented by a unique receipt number shared between the rep and retailer apps to prevent double entry. | C12: Finance / Core | D12: L1 (idempotency basis)
... A29: REQ-IN-08 | B29: The multi-channel split happens on the server at submission; the retailer sees one order and each channel sees only its part. | C29: Ordering | D29: Layer 2

Sheet Risks
A1: # | B1: Risk | C1: Likelihood | D1: Impact | E1: Mitigation | F1: Owning issue
A2: 1 | B2: Module boundaries decay into folder names because nothing enforces them. | C2: High | D2: Pricing logic leaks into Ordering; the exit path to a separate service is lost. | E2: Deptrac plus Pest architecture tests as a merge gate from sprint zero. | F2: BE-F03, BE-F04
A3: 2 | B3: A tenant isolation leak reaches production. | C3: Medium | D3: One channel reads another channel commercial data — the single most damaging failure in this system. | E3: Global scope plus a mandatory isolation test per endpoint, enforced by a coverage gate. | F3: BE-T02, BE-T03, BE-Q02
A4: 3 | B4: Idempotency is implemented per endpoint rather than as middleware. | C4: Medium | D4: Duplicate payments and duplicate receipts under retry — money that cannot be reconciled. | E4: One middleware in Core covering every write, with the exemption list in configuration. | F4: BE-C03
A5: 4 | B5: float appears in a money column. | C5: Medium | D5: Reconciliation differences that cannot be explained or corrected. | E5: Integer columns, a Money value object and an architecture test that fails the build. | F5: BE-C06, BE-F04
A6: 5 | B6: Channel provisioning is written as a synchronous request. | C6: Medium | D6: A blocked request, a timeout, and duplicate channels on retry. | E6: Return provisioning immediately with a job id; make the retry idempotent. | F6: BE-T04, BE-T05
A7: 6 | B7: A sensitive action executes on the first request instead of creating an approval. | C7: Medium | D7: Irreversible deletion or privilege escalation without a second pair of eyes. | E7: A generic approval mechanism in Core that every sensitive action routes through. | F7: BE-C05, BE-A12
A8: 7 | B8: OTP codes stored in clear text or without an attempt cap. | C8: Low | D8: Account takeover across the whole platform, since every identity starts at OTP. | E8: Hashed storage, five-minute expiry, attempt cap and strict per-phone and per-IP limits. | F8: BE-I02, BE-C08
A9: 8 | B9: WhatsApp outage stops all registration. | C9: Medium | D9: The entire platform halts; NEED-S-01 names this explicitly. | E9: A second adapter behind the same contract, switchable at runtime with no release. | F9: BE-X02
A10: 9 | B10: The audit log becomes editable through a maintenance script. | C10: Low | D10: Financial traceability is lost and the two-year retention requirement is void. | E10: No update or delete path at the model layer, plus a test that proves it. | F10: BE-C04
A11: 10 | B11: The zone status route drifts from 034 to the 043 family. | C11: Medium | D11: A silent 404 or 405 in production on a path the frontend depends on. | E11: A contract test pinned to route 034 for zones. | F11: BE-R03

Sheet Jira Import
A1: Issue ID | B1: Issue Key | C1: Issue Type | D1: Summary | E1: Description | F1: Component/s | G1: Priority | H1: Story Points | I1: Epic Name | J1: Epic Link | K1: Sprint | L1: Fix Version/s | M1: Labels | N1: Blocked By
A2: 1 | B2: EP-BE-F | C2: Epic | D2: EP-BE-F — SP-00 Technical foundation | E2: *Covers:* Repository, modules, Deptrac, CI, environments, OpenAPI, queues, health *Volume:* 10 issues / 34 points | F2: backend | G2: High | I2: EP-BE-F | L2: Layer 1 | M2: L1 backend epic
A3: 2 | B3: EP-BE-C | C3: Epic | D3: EP-BE-C — Core module | E3: *Covers:* Envelope, error map, idempotency, audit, approvals, money, state machine base *Volume:* 10 issues / 40 points | F3: backend | G3: High | I3: EP-BE-C | L3: Layer 1 | M3: L1 backend epic
A4: 3 | B4: EP-BE-I | C4: Epic | D4: EP-BE-I — Identity module | E4: *Covers:* Four guards, OTP, registration, sessions, devices, 2FA, API tokens *Volume:* 18 issues / 70 points | F4: backend | G4: High | I4: EP-BE-I | L4: Layer 1 | M4: L1 backend epic
A5: 4 | B5: EP-BE-A | C5: Epic | D5: EP-BE-A — Access module | E5: *Covers:* Permission catalog, roles, SoD, assignments, simulator, temp grants, audit, reviews *Volume:* 16 issues / 67 points | F5: backend | G5: High | I5: EP-BE-A | L5: Layer 1 | M5: L1 backend epic
A6: 5 | B6: EP-BE-R | C6: Epic | D6: EP-BE-R — Reference module | E6: *Covers:* Seven reference entities, FX rates, public refs, import *Volume:* 12 issues / 43 points | F6: backend | G6: High | I6: EP-BE-R | L6: Layer 1 | M6: L1 backend epic
A7: 6 | B7: EP-BE-T | C7: Epic | D7: EP-BE-T — Tenancy module | E7: *Covers:* Channels, provisioning, coverage, limits, isolation, applications *Volume:* 20 issues / 86 points | F7: backend | G7: High | I7: EP-BE-T | L7: Layer 1 | M7: L1 backend epic
A8: 7 | B8: EP-BE-X | C8: Epic | D8: EP-BE-X — Integration module | E8: *Covers:* WhatsApp, SMS fallback, storage, error tracking behind contracts *Volume:* 5 issues / 16 points | F8: backend | G8: High | I8: EP-BE-X | L8: Layer 1 | M8: L1 backend epic
A9: 8 | B9: EP-BE-Q | C9: Epic | D9: EP-BE-Q — Quality and hardening | E9: *Covers:* Architecture tests, isolation suite, contract snapshots, load and security *Volume:* 6 issues / 22 points | F9: backend | G9: High | I9: EP-BE-Q | L9: Layer 1 | M9: L1 backend epic
A10: 9 | B10: BE-F01 | C10: Task | D10: BE-F01 — Repository, Docker and the four environments | E10: *Module:* — *Layer:* Infrastructure *Sprint gate:* SP-00 *Endpoints:* internal h3. Requirements # Provision local Docker, test, staging (production-identical) and production environments. # Laravel 11 skeleton with app/ kept deliberately thin: Kernel, Providers and Console only. # Coding standards: Pint for formatting, Rector for upgrades, Larastan at level 6. # All business logic lives under app-modules/, never under app/. h3. Acceptance criteria * (/) A merge to main deploys automatically to the test environment. * (/) Larastan level 6, Pint and Rector all pass with zero findings. * (/) app/ contains no controller, model or service. h3. Definition of done * (/) Merged to main after peer review; Larastan level 6, Pint and Rector all pass. * (/) Unit and feature tests written and green; engines and money paths at 90%+, endpoints at 75%+. * (/) Deptrac and the Pest architecture suite pass — no cross-module model import, no float in a money path. * (/) Every write accepts X-Idempotency-Key unless it is on the documented exemption list. * (/) Every channel endpoint has an isolation test proving another channel receives 404. * (/) The endpoint declares its permission explicitly and returns the permission key on a 403. * (/) Errors follow the unified envelope and the HTTP status map; no raw Laravel payload escapes. * (/) Every financial, inventory or permission mutation writes an immutable audit entry. * (/) The OpenAPI document is regenerated and the typed client still builds. * (/) Deployed to the test environment and accepted by the product owner. | F10: backend | G10: Highest | H10: 5 | J10: EP-BE-F | K10: L1 backend — SP-00 | L10: Layer 1 | M10: L1, backend, infra, sp-00
A11: 10 | B11: BE-F02 | C11: Task | D11: BE-F02 — Module scaffold with Composer path repositories | E11: *Module:* — *Layer:* Infrastructure *Sprint gate:* SP-00 *Endpoints:* internal h3. Requirements # Create app-modules/ with a local Composer path repository per module (b2b/core, b2b/identity, …). # Each module owns src/Contracts, Domain, Application, Infrastructure, Presentation, Database, Policies, config, lang, tests. # A module declares its dependencies in its own composer.json; a dependency it does not declare is not autoloadable. # Publish a module template so a new module is created identically every time. h3. Acceptance criteria * (/) Importing a class from an undeclared module fails at autoload, not at review. * (/) The six Layer 1 modules exist and boot. * (/) A new module can be scaffolded from the template in one command. h3. Out of scope * nwidart/laravel-modules or any dynamic module loader — explicitly rejected in DOC-10 §1.3. h3. Definition of done * (/) Merged to main after peer review; Larastan level 6, Pint and Rector all pass. * (/) Unit and feature tests written and green; engines and money paths at 90%+, endpoints at 75%+. * (/) Deptrac and the Pest architecture suite pass — no cross-module model import, no float in a money path. * (/) Every write accepts X-Idempotency-Key unless it is on the documented exemption list. * (/) Every channel endpoint has an isolation test proving another channel receives 404. * (/) The endpoint declares its permission explicitly and returns the permission key on a 403. * (/) Errors follow the unified envelope and the HTTP status map; no raw Laravel payload escapes. * (/) Every financial, inventory or permission mutation writes an immutable audit entry. * (/) The OpenAPI document is regenerated and the typed client still builds. * (/) Deployed to the test environment and accepted by the product owner. | F11: backend | G11: Highest | H11: 5 | J11: EP-BE-F | K11: L1 backend — SP-00 | L11: Layer 1 | M11: L1, backend, infra, sp-00 | N11: 9
A12: 11 | B12: BE-F03 | C12: Task | D12: BE-F03 — Deptrac dependency rules in CI | E12: *Module:* — *Layer:* Infrastructure *Sprint gate:* SP-00 *Endpoints:* internal h3. Requirements # Declare the four layers in deptrac.yaml: Foundation, Domain, Coordination, Presentation. # Ruleset: Coordination may depend on Domain and Foundation; Domain on Foundation; Foundation on nothing. # Run Deptrac in the pipeline and fail the build on a violation. h3. Acceptance criteria * (/) A Foundation module importing a Domain class fails the build. * (/) The Deptrac report is attached to every pipeline run. h3. Out of scope * Documenting the rule without enforcing it. A boundary CI does not check is a wish, not a boundary. h3. Definition of done * (/) Merged to main after peer review; Larastan level 6, Pint and Rector all pass. * (/) Unit and feature tests written and green; engines and money paths at 90%+, endpoints at 75%+. * (/) Deptrac and the Pest architecture suite pass — no cross-module model import, no float in a money path. * (/) Every write accepts X-Idempotency-Key unless it is on the documented exemption list. * (/) Every channel endpoint has an isolation test proving another channel receives 404. * (/) The endpoint declares its permission explicitly and returns the permission key on a 403. * (/) Errors follow the unified envelope and the HTTP status map; no raw Laravel payload escapes. * (/) Every financial, inventory or permission mutation writes an immutable audit entry. * (/) The OpenAPI document is regenerated and the typed client still builds. * (/) Deployed to the test environment and accepted by the product owner. | F12: backend | G12: Highest | H12: 3 | J12: EP-BE-F | K12: L1 backend — SP-00 | L12: Layer 1 | M12: L1, backend, infra, sp-00 | N12: 10
A13: 12 | B13: BE-F04 | C13: Task | D13: BE-F04 — Pest architecture tests | E13: *Module:* — *Layer:* Infrastructure *Sprint gate:* SP-00 *Endpoints:* internal h3. Requirements # No module imports another module Eloquent model (Modules\*\Domain\Models is module-private). # No float or double anywhere in a finance or money path. # Every channel controller is behind the channel guard middleware. # Cross-boundary references use identifiers, never Eloquent relations. h3. Acceptance criteria * (/) Each rule has a failing example proving the test actually catches it. * (/) The suite runs in CI on every pull request. h3. Definition of done * (/) Merged to main after peer review; Larastan level 6, Pint and Rector all pass. * (/) Unit and feature tests written and green; engines and money paths at 90%+, endpoints at 75%+. * (/) Deptrac and the Pest architecture suite pass — no cross-module model import, no float in a money path. * (/) Every write accepts X-Idempotency-Key unless it is on the documented exemption list. * (/) Every channel endpoint has an isolation test proving another channel receives 404. * (/) The endpoint declares its permission explicitly and returns the permission key on a 403. * (/) Errors follow the unified envelope and the HTTP status map; no raw Laravel payload escapes. * (/) Every financial, inventory or permission mutation writes an immutable audit entry. * (/) The OpenAPI document is regenerated and the typed client still builds. * (/) Deployed to the test environment and accepted by the product owner. | F13: backend | G13: Highest | H13: 3 | J13: EP-BE-F | K13: L1 backend — SP-00 | L13: Layer 1 | M13: L1, backend, infra, sp-00 | N13: 10
A14: 13 | B14: BE-F05 | C14: Task | D14: BE-F05 — Base migrations and naming conventions | E14: *Module:* — *Layer:* Infrastructure *Sprint gate:* SP-00 *Endpoints:* internal h3. Requirements # Tables plural snake_case; columns snake_case with *_id foreign keys; routes kebab-case and plural. # States are a PHP Enum persisted as a string; events are past tense; jobs and actions are imperative verbs. # Each module owns its migrations, factories and seeders; only composite seeding lives in database/seeders. h3. Acceptance criteria * (/) A convention violation is caught by a static check, not by a reviewer. * (/) Migrations are backward compatible so deployment never requires downtime. h3. Definition of done * (/) Merged to main after peer review; Larastan level 6, Pint and Rector all pass. * (/) Unit and feature tests written and green; engines and money paths at 90%+, endpoints at 75%+. * (/) Deptrac and the Pest architecture suite pass — no cross-module model import, no float in a money path. * (/) Every write accepts X-Idempotency-Key unless it is on the documented exemption list. * (/) Every channel endpoint has an isolation test proving another channel receives 404. * (/) The endpoint declares its permission explicitly and returns the permission key on a 403. * (/) Errors follow the unified envelope and the HTTP status map; no raw Laravel payload escapes. * (/) Every financial, inventory or permission mutation writes an immutable audit entry. * (/) The OpenAPI document is regenerated and the typed client still builds. * (/) Deployed to the test environment and accepted by the product owner. | F14: backend | G14: High | H14: 3 | J14: EP-BE-F | K14: L1 backend — SP-00 | L14: Layer 1 | M14: L1, backend, infra, sp-00 | N14: 10
A15: 14 | B15: BE-F06 | C15: Task | D15: BE-F06 — OpenAPI contract and generated clients | E15: *Module:* — *Layer:* Infrastructure *Sprint gate:* SP-00 *Endpoints:* internal h3. Requirements # Generate the OpenAPI document from the route and resource definitions. # Generate a typed TypeScript client and Zod schemas for the three web frontends. # The catalog fields b (request body), r (data shape) and e (error codes) are the contract of record. h3. Acceptance criteria * (/) A frontend developer writes no type by hand. * (/) A server-side shape change breaks the frontend build rather than failing silently at runtime. h3. Definition of done * (/) Merged to main after peer review; Larastan level 6, Pint and Rector all pass. * (/) Unit and feature tests written and green; engines and money paths at 90%+, endpoints at 75%+. * (/) Deptrac and the Pest architecture suite pass — no cross-module model import, no float in a money path. * (/) Every write accepts X-Idempotency-Key unless it is on the documented exemption list. * (/) Every channel endpoint has an isolation test proving another channel receives 404. * (/) The endpoint declares its permission explicitly and returns the permission key on a 403. * (/) Errors follow the unified envelope and the HTTP status map; no raw Laravel payload escapes. * (/) Every financial, inventory or permission mutation writes an immutable audit entry. * (/) The OpenAPI document is regenerated and the typed client still builds. * (/) Deployed to the test environment and accepted by the product owner. | F15: backend | G15: High | H15: 5 | J15: EP-BE-F | K15: L1 backend — SP-00 | L15: Layer 1 | M15: L1, backend, infra, sp-00 | N15: 9
A16: 15 | B16: BE-F07 | C16: Task | D16: BE-F07 — Queues and Horizon | E16: *Module:* — *Layer:* Infrastructure *Sprint gate:* SP-00 *Endpoints:* internal h3. Requirements # Four queues by priority: critical (OTP, handover, payments, outbox intake), default, media, reports. # Horizon supervises the workers and feeds the system-health screen. # Alert on queue backlog and on rising latency. h3. Acceptance criteria * (/) An OTP job never waits behind a report job. * (/) Horizon shows all four queues with their configured priorities. h3. Definition of done * (/) Merged to main after peer review; Larastan level 6, Pint and Rector all pass. * (/) Unit and feature tests written and green; engines and money paths at 90%+, endpoints at 75%+. * (/) Deptrac and the Pest architecture suite pass — no cross-module model import, no float in a money path. * (/) Every write accepts X-Idempotency-Key unless it is on the documented exemption list. * (/) Every channel endpoint has an isolation test proving another channel receives 404. * (/) The endpoint declares its permission explicitly and returns the permission key on a 403. * (/) Errors follow the unified envelope and the HTTP status map; no raw Laravel payload escapes. * (/) Every financial, inventory or permission mutation writes an immutable audit entry. * (/) The OpenAPI document is regenerated and the typed client still builds. * (/) Deployed to the test environment and accepted by the product owner. | F16: backend | G16: High | H16: 3 | J16: EP-BE-F | K16: L1 backend — SP-00 | L16: Layer 1 | M16: L1, backend, infra, sp-00 | N16: 9
A17: 16 | B17: BE-F08 | C17: Task | D17: BE-F08 — Observability: Sentry, Pulse and alerting | E17: *Module:* — *Layer:* Infrastructure *Sprint gate:* SP-00 *Endpoints:* internal h3. Requirements # Sentry for errors, Pulse for application performance. # Phone numbers and tokens are masked in every log line. # Alerts on queue backlog, response-time regression and error-rate spikes. h3. Acceptance criteria * (/) No log line anywhere contains a full phone number or a token. * (/) An induced 500 reaches Sentry with the request context attached. h3. Definition of done * (/) Merged to main after peer review; Larastan level 6, Pint and Rector all pass. * (/) Unit and feature tests written and green; engines and money paths at 90%+, endpoints at 75%+. * (/) Deptrac and the Pest architecture suite pass — no cross-module model import, no float in a money path. * (/) Every write accepts X-Idempotency-Key unless it is on the documented exemption list. * (/) Every channel endpoint has an isolation test proving another channel receives 404. * (/) The endpoint declares its permission explicitly and returns the permission key on a 403. * (/) Errors follow the unified envelope and the HTTP status map; no raw Laravel payload escapes. * (/) Every financial, inventory or permission mutation writes an immutable audit entry. * (/) The OpenAPI document is regenerated and the typed client still builds. * (/) Deployed to the test environment and accepted by the product owner. | F17: backend | G17: Medium | H17: 3 | J17: EP-BE-F | K17: L1 backend — SP-00 | L17: Layer 1 | M17: L1, backend, infra, sp-00 | N17: 9
A18: 17 | B18: BE-F09 | C18: Story | D18: BE-F09 — Health endpoint | E18: *Module:* Core *Layer:* Foundation *Sprint gate:* SP-00 *Endpoints:* EP-CORE-001 *Unblocks frontend:* FE-CORE-01 h3. Requirements # GET /api/v1/health returns data.status = ok with no authentication and no idempotency key. # Report database, cache and queue reachability. h3. Acceptance criteria * (/) The endpoint answers without a Bearer token. * (/) It is the first endpoint the shared frontend kit calls successfully. h3. Definition of done * (/) Merged to main after peer review; Larastan level 6, Pint and Rector all pass. * (/) Unit and feature tests written and green; engines and money paths at 90%+, endpoints at 75%+. * (/) Deptrac and the Pest architecture suite pass — no cross-module model import, no float in a money path. * (/) Every write accepts X-Idempotency-Key unless it is on the documented exemption list. * (/) Every channel endpoint has an isolation test proving another channel receives 404. * (/) The endpoint declares its permission explicitly and returns the permission key on a 403. * (/) Errors follow the unified envelope and the HTTP status map; no raw Laravel payload escapes. * (/) Every financial, inventory or permission mutation writes an immutable audit entry. * (/) The OpenAPI document is regenerated and the typed client still builds. * (/) Deployed to the test environment and accepted by the product owner. | F18: backend | G18: Highest | H18: 1 | J18: EP-BE-F | K18: L1 backend — SP-00 | L18: Layer 1 | M18: L1, backend, core, sp-00 | N18: 19
